Traceback (most recent call last):
  File "/home/mridul/exdir/process_substitution_for_logging/test.py", line 4, in <module>
    raise ValueError
ValueError

During handling of the above exception, another exception occurred:

Traceback (most recent call last):
  File "/home/mridul/exdir/process_substitution_for_logging/test.py", line 6, in <module>
    raise NameError("Wowza")
NameError: Wowza
